{"primaryContentSections":[{"kind":"declarations","declarations":[{"languages":["swift"],"platforms":["iOS"],"tokens":[{"kind":"keyword","text":"case"},{"kind":"text","text":" "},{"text":"failed","kind":"identifier"}]}]}],"hierarchy":{"paths":[["doc:\/\/com.ibm.verify.ios.sdk\/documentation\/Authentication","doc:\/\/com.ibm.verify.ios.sdk\/documentation\/Authentication\/OAuthProviderError"]]},"schemaVersion":{"major":0,"minor":3,"patch":0},"kind":"symbol","abstract":[{"text":"The authorization attempt failed.","type":"text"}],"sections":[],"metadata":{"title":"OAuthProviderError.failed","fragments":[{"kind":"keyword","text":"case"},{"kind":"text","text":" "},{"kind":"identifier","text":"failed"}],"roleHeading":"Case","role":"symbol","symbolKind":"case","modules":[{"name":"Authentication"}],"externalID":"s:14Authentication18OAuthProviderErrorO6failedyA2CmF"},"identifier":{"url":"doc:\/\/com.ibm.verify.ios.sdk\/documentation\/Authentication\/OAuthProviderError\/failed","interfaceLanguage":"swift"},"variants":[{"paths":["\/documentation\/authentication\/oauthprovidererror\/failed"],"traits":[{"interfaceLanguage":"swift"}]}],"references":{"doc://com.ibm.verify.ios.sdk/documentation/Authentication":{"abstract":[],"title":"Authentication","type":"topic","url":"\/documentation\/authentication","kind":"symbol","role":"collection","identifier":"doc:\/\/com.ibm.verify.ios.sdk\/documentation\/Authentication"},"doc://com.ibm.verify.ios.sdk/documentation/Authentication/OAuthProviderError":{"role":"symbol","url":"\/documentation\/authentication\/oauthprovidererror","title":"OAuthProviderError","fragments":[{"text":"enum","kind":"keyword"},{"text":" ","kind":"text"},{"kind":"identifier","text":"OAuthProviderError"}],"abstract":[{"text":"A type that indicates when OAuth operartion encounters an error.","type":"text"}],"navigatorTitle":[{"text":"OAuthProviderError","kind":"identifier"}],"identifier":"doc:\/\/com.ibm.verify.ios.sdk\/documentation\/Authentication\/OAuthProviderError","kind":"symbol","type":"topic"},"doc://com.ibm.verify.ios.sdk/documentation/Authentication/OAuthProviderError/failed":{"abstract":[{"type":"text","text":"The authorization attempt failed."}],"identifier":"doc:\/\/com.ibm.verify.ios.sdk\/documentation\/Authentication\/OAuthProviderError\/failed","type":"topic","url":"\/documentation\/authentication\/oauthprovidererror\/failed","role":"symbol","title":"OAuthProviderError.failed","kind":"symbol","fragments":[{"kind":"keyword","text":"case"},{"kind":"text","text":" "},{"text":"failed","kind":"identifier"}]}}}