{"primaryContentSections":[{"declarations":[{"languages":["swift"],"platforms":["iOS"],"tokens":[{"kind":"keyword","text":"case"},{"kind":"text","text":" "},{"kind":"identifier","text":"general"},{"text":"(","kind":"text"},{"text":"message","kind":"externalParam"},{"text":": ","kind":"text"},{"text":"String","kind":"typeIdentifier","preciseIdentifier":"s:SS"},{"text":")","kind":"text"}]}],"kind":"declarations"}],"identifier":{"url":"doc:\/\/com.ibm.verify.ios.sdk\/documentation\/Authentication\/OAuthProviderError\/general(message:)","interfaceLanguage":"swift"},"hierarchy":{"paths":[["doc:\/\/com.ibm.verify.ios.sdk\/documentation\/Authentication","doc:\/\/com.ibm.verify.ios.sdk\/documentation\/Authentication\/OAuthProviderError"]]},"schemaVersion":{"patch":0,"minor":3,"major":0},"sections":[],"variants":[{"paths":["\/documentation\/authentication\/oauthprovidererror\/general(message:)"],"traits":[{"interfaceLanguage":"swift"}]}],"abstract":[{"type":"text","text":"The authorization attempt failed for an unknown reason."}],"kind":"symbol","metadata":{"roleHeading":"Case","modules":[{"name":"Authentication"}],"fragments":[{"kind":"keyword","text":"case"},{"kind":"text","text":" "},{"text":"general","kind":"identifier"},{"text":"(","kind":"text"},{"kind":"externalParam","text":"message"},{"kind":"text","text":": "},{"preciseIdentifier":"s:SS","text":"String","kind":"typeIdentifier"},{"text":")","kind":"text"}],"externalID":"s:14Authentication18OAuthProviderErrorO7generalyACSS_tcACmF","symbolKind":"case","role":"symbol","title":"OAuthProviderError.general(message:)"},"references":{"doc://com.ibm.verify.ios.sdk/documentation/Authentication":{"type":"topic","url":"\/documentation\/authentication","kind":"symbol","role":"collection","identifier":"doc:\/\/com.ibm.verify.ios.sdk\/documentation\/Authentication","abstract":[],"title":"Authentication"},"doc://com.ibm.verify.ios.sdk/documentation/Authentication/OAuthProviderError":{"kind":"symbol","identifier":"doc:\/\/com.ibm.verify.ios.sdk\/documentation\/Authentication\/OAuthProviderError","type":"topic","fragments":[{"text":"enum","kind":"keyword"},{"text":" ","kind":"text"},{"kind":"identifier","text":"OAuthProviderError"}],"navigatorTitle":[{"kind":"identifier","text":"OAuthProviderError"}],"url":"\/documentation\/authentication\/oauthprovidererror","abstract":[{"type":"text","text":"A type that indicates when OAuth operartion encounters an error."}],"role":"symbol","title":"OAuthProviderError"},"doc://com.ibm.verify.ios.sdk/documentation/Authentication/OAuthProviderError/general(message:)":{"kind":"symbol","title":"OAuthProviderError.general(message:)","type":"topic","fragments":[{"text":"case","kind":"keyword"},{"kind":"text","text":" "},{"kind":"identifier","text":"general"},{"kind":"text","text":"("},{"kind":"externalParam","text":"message"},{"text":": ","kind":"text"},{"preciseIdentifier":"s:SS","kind":"typeIdentifier","text":"String"},{"text":")","kind":"text"}],"role":"symbol","abstract":[{"type":"text","text":"The authorization attempt failed for an unknown reason."}],"identifier":"doc:\/\/com.ibm.verify.ios.sdk\/documentation\/Authentication\/OAuthProviderError\/general(message:)","url":"\/documentation\/authentication\/oauthprovidererror\/general(message:)"}}}