{"identifier":{"interfaceLanguage":"swift","url":"doc:\/\/com.ibm.verify.ios.sdk\/documentation\/Authentication\/OAuthProviderError\/general(message:)"},"schemaVersion":{"patch":0,"major":0,"minor":3},"kind":"symbol","abstract":[{"type":"text","text":"The authorization attempt failed for an unknown reason."}],"hierarchy":{"paths":[["doc:\/\/com.ibm.verify.ios.sdk\/documentation\/Authentication","doc:\/\/com.ibm.verify.ios.sdk\/documentation\/Authentication\/OAuthProviderError"]]},"primaryContentSections":[{"kind":"declarations","declarations":[{"languages":["swift"],"platforms":["iOS"],"tokens":[{"kind":"keyword","text":"case"},{"kind":"text","text":" "},{"kind":"identifier","text":"general"},{"text":"(","kind":"text"},{"kind":"externalParam","text":"message"},{"text":": ","kind":"text"},{"text":"String","preciseIdentifier":"s:SS","kind":"typeIdentifier"},{"text":")","kind":"text"}]}]}],"sections":[],"metadata":{"roleHeading":"Case","symbolKind":"case","modules":[{"name":"Authentication"}],"title":"OAuthProviderError.general(message:)","fragments":[{"text":"case","kind":"keyword"},{"kind":"text","text":" "},{"kind":"identifier","text":"general"},{"text":"(","kind":"text"},{"kind":"externalParam","text":"message"},{"kind":"text","text":": "},{"kind":"typeIdentifier","preciseIdentifier":"s:SS","text":"String"},{"text":")","kind":"text"}],"externalID":"s:14Authentication18OAuthProviderErrorO7generalyACSS_tcACmF","role":"symbol"},"variants":[{"paths":["\/documentation\/authentication\/oauthprovidererror\/general(message:)"],"traits":[{"interfaceLanguage":"swift"}]}],"references":{"doc://com.ibm.verify.ios.sdk/documentation/Authentication/OAuthProviderError/general(message:)":{"identifier":"doc:\/\/com.ibm.verify.ios.sdk\/documentation\/Authentication\/OAuthProviderError\/general(message:)","type":"topic","role":"symbol","fragments":[{"kind":"keyword","text":"case"},{"kind":"text","text":" "},{"kind":"identifier","text":"general"},{"kind":"text","text":"("},{"kind":"externalParam","text":"message"},{"kind":"text","text":": "},{"text":"String","kind":"typeIdentifier","preciseIdentifier":"s:SS"},{"kind":"text","text":")"}],"kind":"symbol","title":"OAuthProviderError.general(message:)","url":"\/documentation\/authentication\/oauthprovidererror\/general(message:)","abstract":[{"text":"The authorization attempt failed for an unknown reason.","type":"text"}]},"doc://com.ibm.verify.ios.sdk/documentation/Authentication/OAuthProviderError":{"abstract":[{"type":"text","text":"A type that indicates when OAuth operartion encounters an error."}],"kind":"symbol","url":"\/documentation\/authentication\/oauthprovidererror","title":"OAuthProviderError","fragments":[{"kind":"keyword","text":"enum"},{"kind":"text","text":" "},{"text":"OAuthProviderError","kind":"identifier"}],"navigatorTitle":[{"text":"OAuthProviderError","kind":"identifier"}],"identifier":"doc:\/\/com.ibm.verify.ios.sdk\/documentation\/Authentication\/OAuthProviderError","type":"topic","role":"symbol"},"doc://com.ibm.verify.ios.sdk/documentation/Authentication":{"abstract":[],"title":"Authentication","url":"\/documentation\/authentication","identifier":"doc:\/\/com.ibm.verify.ios.sdk\/documentation\/Authentication","role":"collection","kind":"symbol","type":"topic"}}}