{"kind":"symbol","schemaVersion":{"patch":0,"major":0,"minor":3},"metadata":{"symbolKind":"case","role":"symbol","title":"OAuthProviderError.general(message:)","externalID":"s:14Authentication18OAuthProviderErrorO7generalyACSS_tcACmF","modules":[{"name":"Authentication"}],"fragments":[{"text":"case","kind":"keyword"},{"text":" ","kind":"text"},{"kind":"identifier","text":"general"},{"text":"(","kind":"text"},{"text":"message","kind":"externalParam"},{"text":": ","kind":"text"},{"preciseIdentifier":"s:SS","kind":"typeIdentifier","text":"String"},{"text":")","kind":"text"}],"roleHeading":"Case"},"abstract":[{"type":"text","text":"The authorization attempt failed for an unknown reason."}],"sections":[],"identifier":{"interfaceLanguage":"swift","url":"doc:\/\/com.ibm.verify.ios.sdk\/documentation\/Authentication\/OAuthProviderError\/general(message:)"},"hierarchy":{"paths":[["doc:\/\/com.ibm.verify.ios.sdk\/documentation\/Authentication","doc:\/\/com.ibm.verify.ios.sdk\/documentation\/Authentication\/OAuthProviderError"]]},"variants":[{"traits":[{"interfaceLanguage":"swift"}],"paths":["\/documentation\/authentication\/oauthprovidererror\/general(message:)"]}],"primaryContentSections":[{"kind":"declarations","declarations":[{"tokens":[{"kind":"keyword","text":"case"},{"kind":"text","text":" "},{"text":"general","kind":"identifier"},{"kind":"text","text":"("},{"kind":"externalParam","text":"message"},{"text":": ","kind":"text"},{"preciseIdentifier":"s:SS","kind":"typeIdentifier","text":"String"},{"text":")","kind":"text"}],"platforms":["iOS"],"languages":["swift"]}]}],"references":{"doc://com.ibm.verify.ios.sdk/documentation/Authentication/OAuthProviderError":{"role":"symbol","url":"\/documentation\/authentication\/oauthprovidererror","title":"OAuthProviderError","fragments":[{"text":"enum","kind":"keyword"},{"text":" ","kind":"text"},{"kind":"identifier","text":"OAuthProviderError"}],"abstract":[{"text":"A type that indicates when OAuth operartion encounters an error.","type":"text"}],"navigatorTitle":[{"text":"OAuthProviderError","kind":"identifier"}],"identifier":"doc:\/\/com.ibm.verify.ios.sdk\/documentation\/Authentication\/OAuthProviderError","kind":"symbol","type":"topic"},"doc://com.ibm.verify.ios.sdk/documentation/Authentication/OAuthProviderError/general(message:)":{"kind":"symbol","type":"topic","fragments":[{"kind":"keyword","text":"case"},{"kind":"text","text":" "},{"text":"general","kind":"identifier"},{"text":"(","kind":"text"},{"kind":"externalParam","text":"message"},{"kind":"text","text":": "},{"text":"String","preciseIdentifier":"s:SS","kind":"typeIdentifier"},{"kind":"text","text":")"}],"abstract":[{"text":"The authorization attempt failed for an unknown reason.","type":"text"}],"title":"OAuthProviderError.general(message:)","identifier":"doc:\/\/com.ibm.verify.ios.sdk\/documentation\/Authentication\/OAuthProviderError\/general(message:)","url":"\/documentation\/authentication\/oauthprovidererror\/general(message:)","role":"symbol"},"doc://com.ibm.verify.ios.sdk/documentation/Authentication":{"abstract":[],"title":"Authentication","type":"topic","url":"\/documentation\/authentication","kind":"symbol","role":"collection","identifier":"doc:\/\/com.ibm.verify.ios.sdk\/documentation\/Authentication"}}}