{"abstract":[{"type":"text","text":"A type that indicates when OAuth operartion encounters an error."}],"identifier":{"url":"doc:\/\/com.ibm.verify.ios.sdk\/documentation\/Authentication\/OAuthProviderError","interfaceLanguage":"swift"},"sections":[],"metadata":{"modules":[{"name":"Authentication"}],"roleHeading":"Enumeration","externalID":"s:14Authentication18OAuthProviderErrorO","symbolKind":"enum","role":"symbol","navigatorTitle":[{"text":"OAuthProviderError","kind":"identifier"}],"fragments":[{"kind":"keyword","text":"enum"},{"text":" ","kind":"text"},{"kind":"identifier","text":"OAuthProviderError"}],"title":"OAuthProviderError"},"variants":[{"paths":["\/documentation\/authentication\/oauthprovidererror"],"traits":[{"interfaceLanguage":"swift"}]}],"hierarchy":{"paths":[["doc:\/\/com.ibm.verify.ios.sdk\/documentation\/Authentication"]]},"topicSections":[{"anchor":"Enumeration-Cases","generated":true,"identifiers":["doc:\/\/com.ibm.verify.ios.sdk\/documentation\/Authentication\/OAuthProviderError\/failed","doc:\/\/com.ibm.verify.ios.sdk\/documentation\/Authentication\/OAuthProviderError\/general(message:)","doc:\/\/com.ibm.verify.ios.sdk\/documentation\/Authentication\/OAuthProviderError\/invalidResponse"],"title":"Enumeration Cases"},{"identifiers":["doc:\/\/com.ibm.verify.ios.sdk\/documentation\/Authentication\/OAuthProviderError\/errorDescription"],"generated":true,"title":"Instance Properties","anchor":"Instance-Properties"},{"generated":true,"identifiers":["doc:\/\/com.ibm.verify.ios.sdk\/documentation\/Authentication\/OAuthProviderError\/Equatable-Implementations","doc:\/\/com.ibm.verify.ios.sdk\/documentation\/Authentication\/OAuthProviderError\/Error-Implementations","doc:\/\/com.ibm.verify.ios.sdk\/documentation\/Authentication\/OAuthProviderError\/LocalizedError-Implementations"],"anchor":"Default-Implementations","title":"Default Implementations"}],"relationshipsSections":[{"kind":"relationships","type":"conformsTo","title":"Conforms To","identifiers":["doc:\/\/com.ibm.verify.ios.sdk\/10Foundation14LocalizedErrorP","doc:\/\/com.ibm.verify.ios.sdk\/SQ","doc:\/\/com.ibm.verify.ios.sdk\/s5ErrorP","doc:\/\/com.ibm.verify.ios.sdk\/s8SendableP"]}],"schemaVersion":{"minor":3,"patch":0,"major":0},"primaryContentSections":[{"kind":"declarations","declarations":[{"languages":["swift"],"tokens":[{"kind":"keyword","text":"enum"},{"text":" ","kind":"text"},{"kind":"identifier","text":"OAuthProviderError"}],"platforms":["iOS"]}]}],"kind":"symbol","references":{"doc://com.ibm.verify.ios.sdk/10Foundation14LocalizedErrorP":{"type":"unresolvable","identifier":"doc:\/\/com.ibm.verify.ios.sdk\/10Foundation14LocalizedErrorP","title":"Foundation.LocalizedError"},"doc://com.ibm.verify.ios.sdk/documentation/Authentication/OAuthProviderError/failed":{"abstract":[{"type":"text","text":"The authorization attempt failed."}],"identifier":"doc:\/\/com.ibm.verify.ios.sdk\/documentation\/Authentication\/OAuthProviderError\/failed","type":"topic","url":"\/documentation\/authentication\/oauthprovidererror\/failed","role":"symbol","title":"OAuthProviderError.failed","kind":"symbol","fragments":[{"kind":"keyword","text":"case"},{"kind":"text","text":" "},{"text":"failed","kind":"identifier"}]},"doc://com.ibm.verify.ios.sdk/documentation/Authentication/OAuthProviderError/errorDescription":{"url":"\/documentation\/authentication\/oauthprovidererror\/errordescription","type":"topic","title":"errorDescription","fragments":[{"text":"var","kind":"keyword"},{"kind":"text","text":" "},{"text":"errorDescription","kind":"identifier"},{"kind":"text","text":": "},{"text":"String","kind":"typeIdentifier","preciseIdentifier":"s:SS"},{"kind":"text","text":"?"}],"abstract":[],"identifier":"doc:\/\/com.ibm.verify.ios.sdk\/documentation\/Authentication\/OAuthProviderError\/errorDescription","kind":"symbol","role":"symbol"},"doc://com.ibm.verify.ios.sdk/documentation/Authentication/OAuthProviderError/invalidResponse":{"kind":"symbol","url":"\/documentation\/authentication\/oauthprovidererror\/invalidresponse","role":"symbol","type":"topic","abstract":[{"text":"The authorization request received an invalid response.","type":"text"}],"fragments":[{"kind":"keyword","text":"case"},{"kind":"text","text":" "},{"kind":"identifier","text":"invalidResponse"}],"identifier":"doc:\/\/com.ibm.verify.ios.sdk\/documentation\/Authentication\/OAuthProviderError\/invalidResponse","title":"OAuthProviderError.invalidResponse"},"doc://com.ibm.verify.ios.sdk/documentation/Authentication/OAuthProviderError/Error-Implementations":{"abstract":[],"identifier":"doc:\/\/com.ibm.verify.ios.sdk\/documentation\/Authentication\/OAuthProviderError\/Error-Implementations","type":"topic","url":"\/documentation\/authentication\/oauthprovidererror\/error-implementations","role":"collectionGroup","title":"Error Implementations","kind":"article"},"doc://com.ibm.verify.ios.sdk/SQ":{"type":"unresolvable","identifier":"doc:\/\/com.ibm.verify.ios.sdk\/SQ","title":"Swift.Equatable"},"doc://com.ibm.verify.ios.sdk/s8SendableP":{"type":"unresolvable","identifier":"doc:\/\/com.ibm.verify.ios.sdk\/s8SendableP","title":"Swift.Sendable"},"doc://com.ibm.verify.ios.sdk/documentation/Authentication":{"abstract":[],"title":"Authentication","type":"topic","url":"\/documentation\/authentication","kind":"symbol","role":"collection","identifier":"doc:\/\/com.ibm.verify.ios.sdk\/documentation\/Authentication"},"doc://com.ibm.verify.ios.sdk/documentation/Authentication/OAuthProviderError/Equatable-Implementations":{"kind":"article","url":"\/documentation\/authentication\/oauthprovidererror\/equatable-implementations","role":"collectionGroup","type":"topic","abstract":[],"identifier":"doc:\/\/com.ibm.verify.ios.sdk\/documentation\/Authentication\/OAuthProviderError\/Equatable-Implementations","title":"Equatable Implementations"},"doc://com.ibm.verify.ios.sdk/documentation/Authentication/OAuthProviderError/LocalizedError-Implementations":{"abstract":[],"identifier":"doc:\/\/com.ibm.verify.ios.sdk\/documentation\/Authentication\/OAuthProviderError\/LocalizedError-Implementations","type":"topic","url":"\/documentation\/authentication\/oauthprovidererror\/localizederror-implementations","role":"collectionGroup","title":"LocalizedError Implementations","kind":"article"},"doc://com.ibm.verify.ios.sdk/documentation/Authentication/OAuthProviderError":{"role":"symbol","url":"\/documentation\/authentication\/oauthprovidererror","title":"OAuthProviderError","fragments":[{"text":"enum","kind":"keyword"},{"text":" ","kind":"text"},{"kind":"identifier","text":"OAuthProviderError"}],"abstract":[{"text":"A type that indicates when OAuth operartion encounters an error.","type":"text"}],"navigatorTitle":[{"text":"OAuthProviderError","kind":"identifier"}],"identifier":"doc:\/\/com.ibm.verify.ios.sdk\/documentation\/Authentication\/OAuthProviderError","kind":"symbol","type":"topic"},"doc://com.ibm.verify.ios.sdk/s5ErrorP":{"type":"unresolvable","identifier":"doc:\/\/com.ibm.verify.ios.sdk\/s5ErrorP","title":"Swift.Error"},"doc://com.ibm.verify.ios.sdk/documentation/Authentication/OAuthProviderError/general(message:)":{"kind":"symbol","type":"topic","fragments":[{"kind":"keyword","text":"case"},{"kind":"text","text":" "},{"text":"general","kind":"identifier"},{"text":"(","kind":"text"},{"kind":"externalParam","text":"message"},{"kind":"text","text":": "},{"text":"String","preciseIdentifier":"s:SS","kind":"typeIdentifier"},{"kind":"text","text":")"}],"abstract":[{"text":"The authorization attempt failed for an unknown reason.","type":"text"}],"title":"OAuthProviderError.general(message:)","identifier":"doc:\/\/com.ibm.verify.ios.sdk\/documentation\/Authentication\/OAuthProviderError\/general(message:)","url":"\/documentation\/authentication\/oauthprovidererror\/general(message:)","role":"symbol"}}}