{"topicSections":[{"generated":true,"identifiers":["doc:\/\/com.ibm.verify.ios.sdk\/documentation\/Authentication\/OAuthProviderError\/failed","doc:\/\/com.ibm.verify.ios.sdk\/documentation\/Authentication\/OAuthProviderError\/general(message:)","doc:\/\/com.ibm.verify.ios.sdk\/documentation\/Authentication\/OAuthProviderError\/invalidResponse"],"title":"Enumeration Cases","anchor":"Enumeration-Cases"},{"generated":true,"identifiers":["doc:\/\/com.ibm.verify.ios.sdk\/documentation\/Authentication\/OAuthProviderError\/errorDescription"],"title":"Instance Properties","anchor":"Instance-Properties"},{"anchor":"Default-Implementations","title":"Default Implementations","identifiers":["doc:\/\/com.ibm.verify.ios.sdk\/documentation\/Authentication\/OAuthProviderError\/Equatable-Implementations","doc:\/\/com.ibm.verify.ios.sdk\/documentation\/Authentication\/OAuthProviderError\/Error-Implementations","doc:\/\/com.ibm.verify.ios.sdk\/documentation\/Authentication\/OAuthProviderError\/LocalizedError-Implementations"],"generated":true}],"schemaVersion":{"minor":3,"major":0,"patch":0},"kind":"symbol","abstract":[{"type":"text","text":"A type that indicates when OAuth operartion encounters an error."}],"primaryContentSections":[{"declarations":[{"platforms":["iOS"],"tokens":[{"text":"enum","kind":"keyword"},{"text":" ","kind":"text"},{"text":"OAuthProviderError","kind":"identifier"}],"languages":["swift"]}],"kind":"declarations"}],"hierarchy":{"paths":[["doc:\/\/com.ibm.verify.ios.sdk\/documentation\/Authentication"]]},"relationshipsSections":[{"kind":"relationships","identifiers":["doc:\/\/com.ibm.verify.ios.sdk\/10Foundation14LocalizedErrorP","doc:\/\/com.ibm.verify.ios.sdk\/SQ","doc:\/\/com.ibm.verify.ios.sdk\/s5ErrorP","doc:\/\/com.ibm.verify.ios.sdk\/s8SendableP"],"title":"Conforms To","type":"conformsTo"}],"identifier":{"url":"doc:\/\/com.ibm.verify.ios.sdk\/documentation\/Authentication\/OAuthProviderError","interfaceLanguage":"swift"},"metadata":{"fragments":[{"kind":"keyword","text":"enum"},{"kind":"text","text":" "},{"text":"OAuthProviderError","kind":"identifier"}],"modules":[{"name":"Authentication"}],"externalID":"s:14Authentication18OAuthProviderErrorO","symbolKind":"enum","roleHeading":"Enumeration","navigatorTitle":[{"kind":"identifier","text":"OAuthProviderError"}],"title":"OAuthProviderError","role":"symbol"},"sections":[],"variants":[{"traits":[{"interfaceLanguage":"swift"}],"paths":["\/documentation\/authentication\/oauthprovidererror"]}],"references":{"doc://com.ibm.verify.ios.sdk/documentation/Authentication/OAuthProviderError/errorDescription":{"type":"topic","role":"symbol","identifier":"doc:\/\/com.ibm.verify.ios.sdk\/documentation\/Authentication\/OAuthProviderError\/errorDescription","kind":"symbol","title":"errorDescription","url":"\/documentation\/authentication\/oauthprovidererror\/errordescription","abstract":[],"fragments":[{"kind":"keyword","text":"var"},{"text":" ","kind":"text"},{"text":"errorDescription","kind":"identifier"},{"text":": ","kind":"text"},{"text":"String","kind":"typeIdentifier","preciseIdentifier":"s:SS"},{"kind":"text","text":"?"}]},"doc://com.ibm.verify.ios.sdk/documentation/Authentication/OAuthProviderError":{"kind":"symbol","identifier":"doc:\/\/com.ibm.verify.ios.sdk\/documentation\/Authentication\/OAuthProviderError","type":"topic","fragments":[{"text":"enum","kind":"keyword"},{"text":" ","kind":"text"},{"kind":"identifier","text":"OAuthProviderError"}],"navigatorTitle":[{"kind":"identifier","text":"OAuthProviderError"}],"url":"\/documentation\/authentication\/oauthprovidererror","abstract":[{"type":"text","text":"A type that indicates when OAuth operartion encounters an error."}],"role":"symbol","title":"OAuthProviderError"},"doc://com.ibm.verify.ios.sdk/documentation/Authentication/OAuthProviderError/failed":{"identifier":"doc:\/\/com.ibm.verify.ios.sdk\/documentation\/Authentication\/OAuthProviderError\/failed","abstract":[{"type":"text","text":"The authorization attempt failed."}],"role":"symbol","kind":"symbol","url":"\/documentation\/authentication\/oauthprovidererror\/failed","fragments":[{"kind":"keyword","text":"case"},{"text":" ","kind":"text"},{"kind":"identifier","text":"failed"}],"title":"OAuthProviderError.failed","type":"topic"},"doc://com.ibm.verify.ios.sdk/documentation/Authentication/OAuthProviderError/Error-Implementations":{"identifier":"doc:\/\/com.ibm.verify.ios.sdk\/documentation\/Authentication\/OAuthProviderError\/Error-Implementations","title":"Error Implementations","abstract":[],"kind":"article","url":"\/documentation\/authentication\/oauthprovidererror\/error-implementations","type":"topic","role":"collectionGroup"},"doc://com.ibm.verify.ios.sdk/documentation/Authentication/OAuthProviderError/LocalizedError-Implementations":{"abstract":[],"title":"LocalizedError Implementations","role":"collectionGroup","kind":"article","type":"topic","identifier":"doc:\/\/com.ibm.verify.ios.sdk\/documentation\/Authentication\/OAuthProviderError\/LocalizedError-Implementations","url":"\/documentation\/authentication\/oauthprovidererror\/localizederror-implementations"},"doc://com.ibm.verify.ios.sdk/documentation/Authentication/OAuthProviderError/general(message:)":{"kind":"symbol","title":"OAuthProviderError.general(message:)","type":"topic","fragments":[{"text":"case","kind":"keyword"},{"kind":"text","text":" "},{"kind":"identifier","text":"general"},{"kind":"text","text":"("},{"kind":"externalParam","text":"message"},{"text":": ","kind":"text"},{"preciseIdentifier":"s:SS","kind":"typeIdentifier","text":"String"},{"text":")","kind":"text"}],"role":"symbol","abstract":[{"type":"text","text":"The authorization attempt failed for an unknown reason."}],"identifier":"doc:\/\/com.ibm.verify.ios.sdk\/documentation\/Authentication\/OAuthProviderError\/general(message:)","url":"\/documentation\/authentication\/oauthprovidererror\/general(message:)"},"doc://com.ibm.verify.ios.sdk/documentation/Authentication/OAuthProviderError/invalidResponse":{"identifier":"doc:\/\/com.ibm.verify.ios.sdk\/documentation\/Authentication\/OAuthProviderError\/invalidResponse","abstract":[{"type":"text","text":"The authorization request received an invalid response."}],"role":"symbol","kind":"symbol","url":"\/documentation\/authentication\/oauthprovidererror\/invalidresponse","fragments":[{"text":"case","kind":"keyword"},{"kind":"text","text":" "},{"text":"invalidResponse","kind":"identifier"}],"title":"OAuthProviderError.invalidResponse","type":"topic"},"doc://com.ibm.verify.ios.sdk/s8SendableP":{"title":"Swift.Sendable","identifier":"doc:\/\/com.ibm.verify.ios.sdk\/s8SendableP","type":"unresolvable"},"doc://com.ibm.verify.ios.sdk/s5ErrorP":{"title":"Swift.Error","identifier":"doc:\/\/com.ibm.verify.ios.sdk\/s5ErrorP","type":"unresolvable"},"doc://com.ibm.verify.ios.sdk/documentation/Authentication/OAuthProviderError/Equatable-Implementations":{"kind":"article","abstract":[],"role":"collectionGroup","title":"Equatable Implementations","identifier":"doc:\/\/com.ibm.verify.ios.sdk\/documentation\/Authentication\/OAuthProviderError\/Equatable-Implementations","url":"\/documentation\/authentication\/oauthprovidererror\/equatable-implementations","type":"topic"},"doc://com.ibm.verify.ios.sdk/10Foundation14LocalizedErrorP":{"title":"Foundation.LocalizedError","identifier":"doc:\/\/com.ibm.verify.ios.sdk\/10Foundation14LocalizedErrorP","type":"unresolvable"},"doc://com.ibm.verify.ios.sdk/documentation/Authentication":{"type":"topic","url":"\/documentation\/authentication","kind":"symbol","role":"collection","identifier":"doc:\/\/com.ibm.verify.ios.sdk\/documentation\/Authentication","abstract":[],"title":"Authentication"},"doc://com.ibm.verify.ios.sdk/SQ":{"title":"Swift.Equatable","identifier":"doc:\/\/com.ibm.verify.ios.sdk\/SQ","type":"unresolvable"}}}